Workbook

Sheet TABELAS
A2: Tabela 1 Simples Nacional: Anexo 1 – Comércio
A3: Receita Bruta Total em 12 meses | B3: Alíquota | C3: Quanto descontar do valor recolhido | D3: PIS/Pasep | E3: Cofins | F3: IRPJ | G3: CSLL | H3: CPP | I3: ICMS | J3: Faixas
A4: Até R$ 180.000,00 | B4: 0.04 | C4: 0 | D4: 0.0276 | E4: 0.1274 | F4: 0.055 | G4: 0.035 | H4: 0.415 | I4: 0.34 | J4: 1a Faixa
A5: De R$ 180.000,01 a R$ 360.000,00 | B5: 0.073 | C5: 5940 | D5: 0.0276 | E5: 0.1274 | F5: 0.055 | G5: 0.035 | H5: 0.415 | I5: 0.34 | J5: 2a Faixa
A6: De R$ 360.000,01 a R$ 720.000,00 | B6: 0.095 | C6: 13860 | D6: 0.0276 | E6: 0.1274 | F6: 0.055 | G6: 0.035 | H6: 0.42 | I6: 0.335 | J6: 3a Faixa
A7: De R$ 720.000,01 a R$ 1.800.000,00 | B7: 0.107 | C7: 22500 | D7: 0.0276 | E7: 0.1274 | F7: 0.055 | G7: 0.035 | H7: 0.42 | I7: 0.335 | J7: 4a Faixa
A8: De R$ 1.800.000,01 a R$ 3.600.000,00 | B8: 0.143 | C8: 87300 | D8: 0.0276 | E8: 0.1274 | F8: 0.055 | G8: 0.035 | H8: 0.42 | I8: 0.335 | J8: 5a Faixa
A9: De R$ 3.600.000,01 a R$ 4.800.000,00 | B9: 0.19 | C9: 378000 | D9: 0.0613 | E9: 0.2827 | F9: 0.135 | G9: 0.1 | H9: 0.421 | I9: – | J9: 6a Faixa
A11: Tabela 2 Simples Nacional: Anexo 2 – Indústria
A12: Receita Bruta Total em 12 meses | B12: Alíquota | C12: Quanto descontar do valor recolhido
A13: Até R$ 180.000,00 | B13: 0.045 | C13: 0
A14: De R$ 180.000,01 a R$ 360.000,00 | B14: 0.078 | C14: 5940
A15: De R$ 360.000,01 a R$ 720.000,00 | B15: 0.1 | C15: 13860
A16: De R$ 720.000,01 a R$ 1.800.000,00 | B16: 0.112 | C16: 22500
A17: De R$ 1.800.000,01 a R$ R$ 3.600.000,00 | B17: 0.147 | C17: 85500
A18: De R$ 3.600.000,01 a R$ 4.800.000,00 | B18: 0.3 | C18: 720000
A20: Tabela 3 Simples Nacional: Anexo 3 – Prestadores de Serviço
A22: Receita Bruta Total em 12 meses | B22: Alíquota | C22: Quanto descontar do valor recolhido | D22: PIS/Pasep | E22: Cofins | F22: IRPJ | G22: CSLL | H22: CPP | I22: ISS | J22: Faixas
A23: Até R$ 180.000,00 | B23: 0.06 | C23: 0 | D23: 0.0278 | E23: 0.1282 | F23: 0.04 | G23: 0.035 | H23: 0.434 | I23: 0.335 | J23: 1a Faixa
A24: De R$ 180.000,01 a R$ 360.000,00 | B24: 0.112 | C24: 9360 | D24: 0.0305 | E24: 0.1405 | F24: 0.04 | G24: 0.035 | H24: 0.434 | I24: 0.32 | J24: 2a Faixa
A25: De R$ 360.000,01 a R$ 720.000,00 | B25: 0.135 | C25: 17640 | D25: 0.0296 | E25: 0.1364 | F25: 0.04 | G25: 0.035 | H25: 0.434 | I25: 0.325 | J25: 3a Faixa
A26: De R$ 720.000,01 a R$ 1.800.000,00 | B26: 0.16 | C26: 35640 | D26: 0.0296 | E26: 0.1364 | F26: 0.04 | G26: 0.035 | H26: 0.434 | I26: 0.325 | J26: 4a Faixa
A27: De R$ 1.800.000,01 a R$ 3.600.000,00 | B27: 0.21 | C27: 125640 | D27: 0.0278 | E27: 0.1282 | F27: 0.04 | G27: 0.035 | H27: 0.434 | I27: 0.335 | J27: 5a Faixa
A28: De 3.600.000,01 a 4.800.000,00 | B28: 0.33 | C28: 648000 | D28: 0.0347 | E28: 0.1603 | F28: 0.35 | G28: 0.15 | H28: 0.305 | J28: 6a Faixa
A29: Tabela 4 Simples Nacional: Anexo 4 – Prestadores de Serviço
A31: Receita Bruta Total em 12 meses | B31: Alíquota | C31: Quanto descontar do valor recolhido | D31: PIS/Pasep | E31: Cofins | F31: IRPJ | G31: CSLL | I31: ISS | J31: Faixas
A32: Até R$ 180.000,00 | B32: 0.045 | C32: 0 | D32: 0.0383 | E32: 0.1767 | F32: 0.188 | G32: 0.152 | I32: 0.445 | J32: 1a Faixa
A33: De R$ 180.000,01 a R$ 360.000,00 | B33: 0.09 | C33: 8100 | D33: 0.0445 | E33: 0.2055 | F33: 0.198 | G33: 0.152 | I33: 0.4 | J33: 2a Faixa
A34: De R$ 360.000,01 a R$ 720.000,00 | B34: 0.102 | C34: 12420 | D34: 0.0427 | E34: 0.1973 | F34: 0.208 | G34: 0.152 | I34: 0.4 | J34: 3a Faixa
A35: De R$ 720.000,01 a R$ 1.800.000,00 | B35: 0.14 | C35: 39780 | D35: 0.041 | E35: 0.189 | F35: 0.178 | G35: 0.192 | I35: 0.4 | J35: 4a Faixa
A36: De R$ 1.800.000,01 a R$ 3.600.000,00 | B36: 0.22 | C36: 183780 | D36: 0.0392 | E36: 0.1808 | F36: 0.188 | G36: 0.192 | I36: 40,00% (*) | J36: 5a Faixa
A37: De R$ 3.600.000,01 a R$ 4.800.000,00 | B37: 0.33 | C37: 828000 | D37: 0.0445 | E37: 0.2055 | F37: 0.535 | G37: 0.215 | I37: – | J37: 6a Faixa
D38: PIS/Pasep | E38: Cofins | F38: IRPJ | G38: CSLL | I38: ISS | J38: Faixa
A39: Tabela 5 Simples Nacional: Anexo 5 – Prestadores de Serviço | D39: Alíquota efetiva 5%) x 6,54 | E39: (Alíquota efetiva 5%) x 30,13% | F39: Alíquota efetiva 5%) x 31,33% | G39: (Alíquota efetiva 5%) x 32,00% | I39: Percentual de ISS fixo em 5% | J39: 5a Faixa, com alíquota efetiva superior a 12,5%
A41: Receita Bruta Total em 12 meses | B41: Alíquota | C41: Quanto descontar do valor recolhido | D41: CPP | E41: ISS | F41: CSLL | G41: IRPJ | H41: Cofins | I41: Faixas | J41: PIS/Pasep
A42: Até R$ 180.000,00 | B42: 0.155 | C42: 0 | D42: 0.2885 | E42: 0.14 | F42: 0.15 | G42: 0.25 | H42: 0.141 | I42: 1a Faixa | J42: 0.0305
A43: De 180.000,01 a 360.000,00 | B43: 0.18 | C43: 4500 | D43: 0.2785 | E43: 0.17 | F43: 0.15 | G43: 0.23 | H43: 0.141 | I43: 2a Faixa | J43: 0.0305
A44: De 360.000,01 a 720.000,00 | B44: 0.195 | C44: 9900 | D44: 0.2385 | E44: 0.19 | F44: 0.15 | G44: 0.24 | H44: 0.1492 | I44: 3a Faixa | J44: 0.0323
A45: De 720.000,01 a 1.800.000,00 | B45: 0.205 | C45: 17100 | D45: 0.2385 | E45: 0.21 | F45: 0.15 | G45: 0.21 | H45: 0.1574 | I45: 4a Faixa | J45: 0.0341
A46: De 1.800.000,01 a 3.600.000,00 | B46: 0.23 | C46: 62100 | D46: 0.2385 | E46: 0.235 | F46: 0.125 | G46: 0.23 | H46: 0.141 | I46: 5a Faixa | J46: 0.0305
...

Sheet RBT
D2: 45261 | E2: 100000
D3: 45231 | E3: 100000
D4: 45200 | E4: 100000 | H4: Mês/Ano | I4: Mês | J4: Acumulada | K4: PIS | L4: COFINS | M4: IRPJ | N4: CSLL | O4: IPI | P4: ICMS | Q4: INSS - Patr.
D5: 45170 | E5: 100000 | H5: 44896 | I5: 42343.77 | J5: 1458034.9 | K5: 106.48 | L5: 491.63 | M5: 217.72 | N5: 138.54 | O5: 77.27 | P5: 1297.28 | Q5: 1616.18
D6: 45139 | E6: 100000
D7: 45108 | E7: 100000
D8: 45078 | E8: 100000
D9: 45047 | E9: 100000
D10: 45017 | E10: 100000
D11: 44986 | E11: 100000
D12: 44958 | E12: 100000
D13: 44927 | E13: 100000
D14: 44896 | E14: 200048.11
D15: 44866 | E15: 433796.09
D16: 44835 | E16: 363654.01
D17: 44805 | E17: 446968.74
... D27: 44501 | E27: 433796.09
E28: =SUM(E16:E27) -> 4695422.1

Sheet SN industria
A1: SIMULAÇÃO FATURAMENTO
A2: Período | B2: Receita
A3: Mês/Ano | B3: Mês | C3: Acumulada | D3: PIS | E3: COFINS | F3: IRPJ | G3: CSLL | H3: INSS/CPP | I3: ICMS | J3: VALOR DAS
A4: 44562 | B4: 0 | C4: 0 | D4: =B4*D8 -> #DIV/0! | E4: =B4*E8 -> #DIV/0! | F4: =B4*F8 -> #DIV/0! | G4: =B4*G8 -> #DIV/0! | H4: =B4*H8 -> #DIV/0! | I4: =B4*I8 -> #DIV/0! | J4: =SUM(D4:I4) -> #DIV/0!
A5: ANEXO | B5: ALIQ NOMINAL | C5: PARCELA DEDUZIR | D5: ALIQ EFETIVA | E5: ALIQ EFETIVA | F5: ALIQ EFETIVA | G5: ALIQ EFETIVA | H5: ALIQ EFETIVA | I5: ALIQ EFETIVA
A6: I | B6: =TABELAS!B9 -> 0.19 | C6: =TABELAS!C9 -> 378000 | D6: =((C4*B6)-C6)/C4 -> #DIV/0! | E6: =D6 -> #DIV/0! | F6: =E6 -> #DIV/0! | G6: =F6 -> #DIV/0! | H6: =G6 -> #DIV/0! | I6: =H6 -> #DIV/0!
D7: =TABELAS!D7 -> 0.0276 | E7: =TABELAS!E7 -> 0.1274 | F7: =TABELAS!F7 -> 0.055 | G7: =TABELAS!G7 -> 0.035 | H7: =TABELAS!H7 -> 0.42 | I7: =TABELAS!I7 -> 0.335
D8: =D7*D6 -> #DIV/0! | E8: =E7*E6 -> #DIV/0! | F8: =F7*F6 -> #DIV/0! | G8: =G7*G6 -> #DIV/0! | H8: =H7*H6 -> #DIV/0! | I8: =I7*I6 -> #DIV/0!
A9: 44593 | B9: 0 | C9: 0 | D9: =B9*D13 -> #DIV/0! | E9: =B9*E13 -> #DIV/0! | F9: =B9*F13 -> #DIV/0! | G9: =B9*G13 -> #DIV/0! | H9: =B9*H13 -> #DIV/0! | I9: =B9*I13 -> #DIV/0! | J9: =SUM(D9:I9) -> #DIV/0!
A10: ANEXO | B10: ALIQ NOMINAL | C10: PARCELA DEDUZIR | D10: ALIQ EFETIVA | E10: ALIQ EFETIVA | F10: ALIQ EFETIVA | G10: ALIQ EFETIVA | H10: ALIQ EFETIVA | I10: ALIQ EFETIVA
A11: =A6 -> I | B11: =TABELAS!B7 -> 0.107 | C11: =TABELAS!C7 -> 22500 | D11: =((C9*B11)-C11)/C9 -> #DIV/0! | E11: =D11 -> #DIV/0! | F11: =E11 -> #DIV/0! | G11: =F11 -> #DIV/0! | H11: =G11 -> #DIV/0! | I11: =H11 -> #DIV/0!
D12: =TABELAS!D25 -> 0.0296 | E12: =TABELAS!E25 -> 0.1364 | F12: =TABELAS!F25 -> 0.04 | G12: =TABELAS!G25 -> 0.035 | H12: =TABELAS!H25 -> 0.434 | I12: =TABELAS!I25 -> 0.325
D13: =D12*D11 -> #DIV/0! | E13: =E12*E11 -> #DIV/0! | F13: =F12*F11 -> #DIV/0! | G13: =G12*G11 -> #DIV/0! | H13: =H12*H11 -> #DIV/0! | I13: =I12*I11 -> #DIV/0!
A14: 44621 | B14: 0 | C14: 0 | D14: =B14*D18 -> #DIV/0! | E14: =B14*E18 -> #DIV/0! | F14: =B14*F18 -> #DIV/0! | G14: =B14*G18 -> #DIV/0! | H14: =B14*H18 -> #DIV/0! | I14: =B14*I18 -> #DIV/0! | J14: =SUM(D14:I14) -> #DIV/0!
A15: ANEXO | B15: ALIQ NOMINAL | C15: PARCELA DEDUZIR | D15: ALIQ EFETIVA | E15: ALIQ EFETIVA | F15: ALIQ EFETIVA | G15: ALIQ EFETIVA | H15: ALIQ EFETIVA | I15: ALIQ EFETIVA
A16: =A11 -> I | B16: =TABELAS!B7 -> 0.107 | C16: =TABELAS!C7 -> 22500 | D16: =((C14*B16)-C16)/C14 -> #DIV/0! | E16: =D16 -> #DIV/0! | F16: =E16 -> #DIV/0! | G16: =F16 -> #DIV/0! | H16: =G16 -> #DIV/0! | I16: =H16 -> #DIV/0!
D17: =TABELAS!D25 -> 0.0296 | E17: =TABELAS!E25 -> 0.1364 | F17: =TABELAS!F25 -> 0.04 | G17: =TABELAS!G25 -> 0.035 | H17: =TABELAS!H25 -> 0.434 | I17: =TABELAS!I25 -> 0.325
D18: =D17*D16 -> #DIV/0! | E18: =E17*E16 -> #DIV/0! | F18: =F17*F16 -> #DIV/0! | G18: =G17*G16 -> #DIV/0! | H18: =H17*H16 -> #DIV/0! | I18: =I17*I16 -> #DIV/0!
A19: 44652 | B19: 0 | C19: 0 | D19: =B19*D23 -> #DIV/0! | E19: =B19*E23 -> #DIV/0! | F19: =B19*F23 -> #DIV/0! | G19: =B19*G23 -> #DIV/0! | H19: =B19*H23 -> #DIV/0! | I19: =B19*I23 -> #DIV/0! | J19: =SUM(D19:I19) -> #DIV/0!
A20: ANEXO | B20: ALIQ NOMINAL | C20: PARCELA DEDUZIR | D20: ALIQ EFETIVA | E20: ALIQ EFETIVA | F20: ALIQ EFETIVA | G20: ALIQ EFETIVA | H20: ALIQ EFETIVA | I20: ALIQ EFETIVA
A21: =A16 -> I | B21: =TABELAS!B7 -> 0.107 | C21: =TABELAS!C7 -> 22500 | D21: =((C19*B21)-C21)/C19 -> #DIV/0! | E21: =D21 -> #DIV/0! | F21: =E21 -> #DIV/0! | G21: =F21 -> #DIV/0! | H21: =G21 -> #DIV/0! | I21: =H21 -> #DIV/0!
D22: =TABELAS!D25 -> 0.0296 | E22: =TABELAS!E25 -> 0.1364 | F22: =TABELAS!F25 -> 0.04 | G22: =TABELAS!G25 -> 0.035 | H22: =TABELAS!H25 -> 0.434 | I22: =TABELAS!I25 -> 0.325
D23: =D22*D21 -> #DIV/0! | E23: =E22*E21 -> #DIV/0! | F23: =F22*F21 -> #DIV/0! | G23: =G22*G21 -> #DIV/0! | H23: =H22*H21 -> #DIV/0! | I23: =I22*I21 -> #DIV/0!
A24: 44682 | B24: 0 | C24: 0 | D24: =B24*D28 -> #DIV/0! | E24: =B24*E28 -> #DIV/0! | F24: =B24*F28 -> #DIV/0! | G24: =B24*G28 -> #DIV/0! | H24: =B24*H28 -> #DIV/0! | I24: =B24*I28 -> #DIV/0! | J24: =SUM(D24:I24) -> #DIV/0!
A25: ANEXO | B25: ALIQ NOMINAL | C25: PARCELA DEDUZIR | D25: ALIQ EFETIVA | E25: ALIQ EFETIVA | F25: ALIQ EFETIVA | G25: ALIQ EFETIVA | H25: ALIQ EFETIVA | I25: ALIQ EFETIVA
A26: l | B26: =TABELAS!B25 -> 0.135 | C26: =TABELAS!C25 -> 17640 | D26: =((C24*B26)-C26)/C24 -> #DIV/0! | E26: =D26 -> #DIV/0! | F26: =E26 -> #DIV/0! | G26: =F26 -> #DIV/0! | H26: =G26 -> #DIV/0! | I26: =H26 -> #DIV/0!
D27: =TABELAS!D25 -> 0.0296 | E27: =TABELAS!E25 -> 0.1364 | F27: =TABELAS!F25 -> 0.04 | G27: =TABELAS!G25 -> 0.035 | H27: =TABELAS!H25 -> 0.434 | I27: =TABELAS!I25 -> 0.325
D28: =D27*D26 -> #DIV/0! | E28: =E27*E26 -> #DIV/0! | F28: =F27*F26 -> #DIV/0! | G28: =G27*G26 -> #DIV/0! | H28: =H27*H26 -> #DIV/0! | I28: =I27*I26 -> #DIV/0!
A29: 44713 | B29: 0 | C29: 0 | D29: =B29*D33 -> #DIV/0! | E29: =B29*E33 -> #DIV/0! | F29: =B29*F33 -> #DIV/0! | G29: =B29*G33 -> #DIV/0! | H29: =B29*H33 -> #DIV/0! | I29: =B29*I33 -> #DIV/0! | J29: =SUM(D29:I29) -> #DIV/0!
A30: ANEXO | B30: ALIQ NOMINAL | C30: PARCELA DEDUZIR | D30: ALIQ EFETIVA | E30: ALIQ EFETIVA | F30: ALIQ EFETIVA | G30: ALIQ EFETIVA | H30: ALIQ EFETIVA | I30: ALIQ EFETIVA
A31: l | B31: =TABELAS!B25 -> 0.135 | C31: =TABELAS!C25 -> 17640 | D31: =((C29*B31)-C31)/C29 -> #DIV/0! | E31: =D31 -> #DIV/0! | F31: =E31 -> #DIV/0! | G31: =F31 -> #DIV/0! | H31: =G31 -> #DIV/0! | I31: =H31 -> #DIV/0!
D32: =TABELAS!D25 -> 0.0296 | E32: =TABELAS!E25 -> 0.1364 | F32: =TABELAS!F25 -> 0.04 | G32: =TABELAS!G25 -> 0.035 | H32: =TABELAS!H25 -> 0.434 | I32: =TABELAS!I25 -> 0.325
D33: =D32*D31 -> #DIV/0! | E33: =E32*E31 -> #DIV/0! | F33: =F32*F31 -> #DIV/0! | G33: =G32*G31 -> #DIV/0! | H33: =H32*H31 -> #DIV/0! | I33: =I32*I31 -> #DIV/0!
A34: 44743 | B34: 0 | C34: 0 | D34: =B34*D38 -> #DIV/0! | E34: =B34*E38 -> #DIV/0! | F34: =B34*F38 -> #DIV/0! | G34: =B34*G38 -> #DIV/0! | H34: =B34*H38 -> #DIV/0! | I34: =B34*I38 -> #DIV/0! | J34: =SUM(D34:I34) -> #DIV/0!
A35: ANEXO | B35: ALIQ NOMINAL | C35: PARCELA DEDUZIR | D35: ALIQ EFETIVA | E35: ALIQ EFETIVA | F35: ALIQ EFETIVA | G35: ALIQ EFETIVA | H35: ALIQ EFETIVA | I35: ALIQ EFETIVA
A36: l | B36: =TABELAS!B25 -> 0.135 | C36: =TABELAS!C25 -> 17640 | D36: =((C34*B36)-C36)/C34 -> #DIV/0! | E36: =D36 -> #DIV/0! | F36: =E36 -> #DIV/0! | G36: =F36 -> #DIV/0! | H36: =G36 -> #DIV/0! | I36: =H36 -> #DIV/0!
D37: =TABELAS!D25 -> 0.0296 | E37: =TABELAS!E25 -> 0.1364 | F37: =TABELAS!F25 -> 0.04 | G37: =TABELAS!G25 -> 0.035 | H37: =TABELAS!H25 -> 0.434 | I37: =TABELAS!I25 -> 0.325
D38: =D37*D36 -> #DIV/0! | E38: =E37*E36 -> #DIV/0! | F38: =F37*F36 -> #DIV/0! | G38: =G37*G36 -> #DIV/0! | H38: =H37*H36 -> #DIV/0! | I38: =I37*I36 -> #DIV/0!
A39: 44774 | B39: 0 | C39: 0 | D39: =B39*D43 -> #DIV/0! | E39: =B39*E43 -> #DIV/0! | F39: =B39*F43 -> #DIV/0! | G39: =B39*G43 -> #DIV/0! | H39: =B39*H43 -> #DIV/0! | I39: =B39*I43 -> #DIV/0! | J39: =SUM(D39:I39) -> #DIV/0!
A40: ANEXO | B40: ALIQ NOMINAL | C40: PARCELA DEDUZIR | D40: ALIQ EFETIVA | E40: ALIQ EFETIVA | F40: ALIQ EFETIVA | G40: ALIQ EFETIVA | H40: ALIQ EFETIVA | I40: ALIQ EFETIVA
...

Sheet SN comercio
A5: SIMULAÇÃO FATURAMENTO
A6: Período | B6: Receita
A7: Mês/Ano | B7: Mês | C7: Acumulada | D7: PIS | E7: COFINS | F7: IRPJ | G7: CSLL | H7: INSS/CPP | I7: ICMS | J7: VALOR DAS
A8: 45261 | B8: 0 | C8: 309185.85 | D8: =B8*D12 -> 0 | E8: =B8*E12 -> 0 | F8: =B8*F12 -> 0 | G8: =B8*G12 -> 0 | H8: =B8*H12 -> 0 | I8: =B8*I12 -> 0 | J8: =SUM(D8:I8) -> 0
A9: ANEXO | B9: ALIQ NOMINAL | C9: PARCELA DEDUZIR | D9: ALIQ EFETIVA | E9: ALIQ EFETIVA | F9: ALIQ EFETIVA | G9: ALIQ EFETIVA | H9: ALIQ EFETIVA | I9: ALIQ EFETIVA
A10: I | B10: =TABELAS!B5 -> 0.073 | C10: =TABELAS!C5 -> 5940 | D10: =((C8*B10)-C10)/C8 -> 0.053788254 | E10: =D10 -> 0.053788254 | F10: =E10 -> 0.053788254 | G10: =F10 -> 0.053788254 | H10: =G10 -> 0.053788254 | I10: =H10 -> 0.053788254
D11: =TABELAS!D5 -> 0.0276 | E11: =TABELAS!E5 -> 0.1274 | F11: =TABELAS!F5 -> 0.055 | G11: =TABELAS!G5 -> 0.035 | H11: =TABELAS!H5 -> 0.415 | I11: =TABELAS!I5 -> 0.34
D12: =D11*D10 -> 0.0014845558 | E12: =E11*E10 -> 0.0068526236 | F12: =F11*F10 -> 0.002958354 | G12: =G11*G10 -> 0.0018825889 | H12: =H11*H10 -> 0.022322125 | I12: =I11*I10 -> 0.018288006
A13: 41244 | B13: 0 | C13: 521176.19 | D13: =B13*D17 -> 0 | E13: =B13*E17 -> 0 | F13: =B13*F17 -> 0 | G13: =B13*G17 -> 0 | H13: =B13*H17 -> 0 | I13: =B13*I17 -> 0 | J13: =SUM(D13:I13) -> 0
A14: ANEXO | B14: ALIQ NOMINAL | C14: PARCELA DEDUZIR | D14: ALIQ EFETIVA | E14: ALIQ EFETIVA | F14: ALIQ EFETIVA | G14: ALIQ EFETIVA | H14: ALIQ EFETIVA | I14: ALIQ EFETIVA
A15: III | B15: =TABELAS!B25 -> 0.135 | C15: =TABELAS!C25 -> 17640 | D15: =((C13*B15)-C15)/C13 -> 0.10115348 | E15: =D15 -> 0.10115348 | F15: =E15 -> 0.10115348 | G15: =F15 -> 0.10115348 | H15: =G15 -> 0.10115348 | I15: =H15 -> 0.10115348
D16: =TABELAS!D25 -> 0.0296 | E16: =TABELAS!E25 -> 0.1364 | F16: =TABELAS!F25 -> 0.04 | G16: =TABELAS!G25 -> 0.035 | H16: =TABELAS!H25 -> 0.434 | I16: =TABELAS!I25 -> 0.325
D17: =D16*D15 -> 0.002994143 | E17: =E16*E15 -> 0.013797335 | F17: =F16*F15 -> 0.0040461392 | G17: =G16*G15 -> 0.0035403718 | H17: =H16*H15 -> 0.043900611 | I17: =I16*I15 -> 0.032874881
A18: 44621 | B18: 0 | C18: 0 | D18: =B18*D22 -> #DIV/0! | E18: =B18*E22 -> #DIV/0! | F18: =B18*F22 -> #DIV/0! | G18: =B18*G22 -> #DIV/0! | H18: =B18*H22 -> #DIV/0! | I18: =B18*I22 -> #DIV/0! | J18: =SUM(D18:I18) -> #DIV/0!
A19: ANEXO | B19: ALIQ NOMINAL | C19: PARCELA DEDUZIR | D19: ALIQ EFETIVA | E19: ALIQ EFETIVA | F19: ALIQ EFETIVA | G19: ALIQ EFETIVA | H19: ALIQ EFETIVA | I19: ALIQ EFETIVA
A20: III | B20: =TABELAS!B7 -> 0.107 | C20: =TABELAS!C7 -> 22500 | D20: =((C18*B20)-C20)/C18 -> #DIV/0! | E20: =D20 -> #DIV/0! | F20: =E20 -> #DIV/0! | G20: =F20 -> #DIV/0! | H20: =G20 -> #DIV/0! | I20: =H20 -> #DIV/0!
D21: =TABELAS!D25 -> 0.0296 | E21: =TABELAS!E25 -> 0.1364 | F21: =TABELAS!F25 -> 0.04 | G21: =TABELAS!G25 -> 0.035 | H21: =TABELAS!H25 -> 0.434 | I21: =TABELAS!I25 -> 0.325
D22: =D21*D20 -> #DIV/0! | E22: =E21*E20 -> #DIV/0! | F22: =F21*F20 -> #DIV/0! | G22: =G21*G20 -> #DIV/0! | H22: =H21*H20 -> #DIV/0! | I22: =I21*I20 -> #DIV/0!
A23: 44652 | B23: 0 | C23: 0 | D23: =B23*D27 -> #DIV/0! | E23: =B23*E27 -> #DIV/0! | F23: =B23*F27 -> #DIV/0! | G23: =B23*G27 -> #DIV/0! | H23: =B23*H27 -> #DIV/0! | I23: =B23*I27 -> #DIV/0! | J23: =SUM(D23:I23) -> #DIV/0!
A24: ANEXO | B24: ALIQ NOMINAL | C24: PARCELA DEDUZIR | D24: ALIQ EFETIVA | E24: ALIQ EFETIVA | F24: ALIQ EFETIVA | G24: ALIQ EFETIVA | H24: ALIQ EFETIVA | I24: ALIQ EFETIVA
A25: III | B25: =TABELAS!B7 -> 0.107 | C25: =TABELAS!C7 -> 22500 | D25: =((C23*B25)-C25)/C23 -> #DIV/0! | E25: =D25 -> #DIV/0! | F25: =E25 -> #DIV/0! | G25: =F25 -> #DIV/0! | H25: =G25 -> #DIV/0! | I25: =H25 -> #DIV/0!
D26: =TABELAS!D25 -> 0.0296 | E26: =TABELAS!E25 -> 0.1364 | F26: =TABELAS!F25 -> 0.04 | G26: =TABELAS!G25 -> 0.035 | H26: =TABELAS!H25 -> 0.434 | I26: =TABELAS!I25 -> 0.325
D27: =D26*D25 -> #DIV/0! | E27: =E26*E25 -> #DIV/0! | F27: =F26*F25 -> #DIV/0! | G27: =G26*G25 -> #DIV/0! | H27: =H26*H25 -> #DIV/0! | I27: =I26*I25 -> #DIV/0!
A28: 44682 | B28: 0 | C28: 0 | D28: =B28*D32 -> #DIV/0! | E28: =B28*E32 -> #DIV/0! | F28: =B28*F32 -> #DIV/0! | G28: =B28*G32 -> #DIV/0! | H28: =B28*H32 -> #DIV/0! | I28: =B28*I32 -> #DIV/0! | J28: =SUM(D28:I28) -> #DIV/0!
A29: ANEXO | B29: ALIQ NOMINAL | C29: PARCELA DEDUZIR | D29: ALIQ EFETIVA | E29: ALIQ EFETIVA | F29: ALIQ EFETIVA | G29: ALIQ EFETIVA | H29: ALIQ EFETIVA | I29: ALIQ EFETIVA
A30: III | B30: =TABELAS!B25 -> 0.135 | C30: =TABELAS!C25 -> 17640 | D30: =((C28*B30)-C30)/C28 -> #DIV/0! | E30: =D30 -> #DIV/0! | F30: =E30 -> #DIV/0! | G30: =F30 -> #DIV/0! | H30: =G30 -> #DIV/0! | I30: =H30 -> #DIV/0!
D31: =TABELAS!D25 -> 0.0296 | E31: =TABELAS!E25 -> 0.1364 | F31: =TABELAS!F25 -> 0.04 | G31: =TABELAS!G25 -> 0.035 | H31: =TABELAS!H25 -> 0.434 | I31: =TABELAS!I25 -> 0.325
D32: =D31*D30 -> #DIV/0! | E32: =E31*E30 -> #DIV/0! | F32: =F31*F30 -> #DIV/0! | G32: =G31*G30 -> #DIV/0! | H32: =H31*H30 -> #DIV/0! | I32: =I31*I30 -> #DIV/0!
A33: 44713 | B33: 0 | C33: 0 | D33: =B33*D37 -> #DIV/0! | E33: =B33*E37 -> #DIV/0! | F33: =B33*F37 -> #DIV/0! | G33: =B33*G37 -> #DIV/0! | H33: =B33*H37 -> #DIV/0! | I33: =B33*I37 -> #DIV/0! | J33: =SUM(D33:I33) -> #DIV/0!
A34: ANEXO | B34: ALIQ NOMINAL | C34: PARCELA DEDUZIR | D34: ALIQ EFETIVA | E34: ALIQ EFETIVA | F34: ALIQ EFETIVA | G34: ALIQ EFETIVA | H34: ALIQ EFETIVA | I34: ALIQ EFETIVA
A35: III | B35: =TABELAS!B25 -> 0.135 | C35: =TABELAS!C25 -> 17640 | D35: =((C33*B35)-C35)/C33 -> #DIV/0! | E35: =D35 -> #DIV/0! | F35: =E35 -> #DIV/0! | G35: =F35 -> #DIV/0! | H35: =G35 -> #DIV/0! | I35: =H35 -> #DIV/0!
D36: =TABELAS!D25 -> 0.0296 | E36: =TABELAS!E25 -> 0.1364 | F36: =TABELAS!F25 -> 0.04 | G36: =TABELAS!G25 -> 0.035 | H36: =TABELAS!H25 -> 0.434 | I36: =TABELAS!I25 -> 0.325
D37: =D36*D35 -> #DIV/0! | E37: =E36*E35 -> #DIV/0! | F37: =F36*F35 -> #DIV/0! | G37: =G36*G35 -> #DIV/0! | H37: =H36*H35 -> #DIV/0! | I37: =I36*I35 -> #DIV/0!
A38: 44743 | B38: 0 | C38: 0 | D38: =B38*D42 -> #DIV/0! | E38: =B38*E42 -> #DIV/0! | F38: =B38*F42 -> #DIV/0! | G38: =B38*G42 -> #DIV/0! | H38: =B38*H42 -> #DIV/0! | I38: =B38*I42 -> #DIV/0! | J38: =SUM(D38:I38) -> #DIV/0!
A39: ANEXO | B39: ALIQ NOMINAL | C39: PARCELA DEDUZIR | D39: ALIQ EFETIVA | E39: ALIQ EFETIVA | F39: ALIQ EFETIVA | G39: ALIQ EFETIVA | H39: ALIQ EFETIVA | I39: ALIQ EFETIVA
A40: III | B40: =TABELAS!B25 -> 0.135 | C40: =TABELAS!C25 -> 17640 | D40: =((C38*B40)-C40)/C38 -> #DIV/0! | E40: =D40 -> #DIV/0! | F40: =E40 -> #DIV/0! | G40: =F40 -> #DIV/0! | H40: =G40 -> #DIV/0! | I40: =H40 -> #DIV/0!
D41: =TABELAS!D25 -> 0.0296 | E41: =TABELAS!E25 -> 0.1364 | F41: =TABELAS!F25 -> 0.04 | G41: =TABELAS!G25 -> 0.035 | H41: =TABELAS!H25 -> 0.434 | I41: =TABELAS!I25 -> 0.325
D42: =D41*D40 -> #DIV/0! | E42: =E41*E40 -> #DIV/0! | F42: =F41*F40 -> #DIV/0! | G42: =G41*G40 -> #DIV/0! | H42: =H41*H40 -> #DIV/0! | I42: =I41*I40 -> #DIV/0!
A43: 44774 | B43: 0 | C43: 0 | D43: =B43*D47 -> #DIV/0! | E43: =B43*E47 -> #DIV/0! | F43: =B43*F47 -> #DIV/0! | G43: =B43*G47 -> #DIV/0! | H43: =B43*H47 -> #DIV/0! | I43: =B43*I47 -> #DIV/0! | J43: =SUM(D43:I43) -> #DIV/0!
A44: ANEXO | B44: ALIQ NOMINAL | C44: PARCELA DEDUZIR | D44: ALIQ EFETIVA | E44: ALIQ EFETIVA | F44: ALIQ EFETIVA | G44: ALIQ EFETIVA | H44: ALIQ EFETIVA | I44: ALIQ EFETIVA
...

Sheet SN Serviço
A1: SIMULAÇÃO FATURAMENTO | L1: DIFERENÇA
A2: Período | B2: Receita | M2: VALOR DEVIDO | N2: VALOR PAGO | O2: VALOR A PAGAR
A3: Mês/Ano | B3: Mês | C3: Acumulada | D3: PIS | E3: COFINS | F3: IRPJ | G3: CSLL | H3: INSS/CPP | I3: ISS | L3: 44562 | M3: =J4 -> 5280 | N3: 14791.15 | O3: =M3-N3 -> -9511.15
A4: 45261 | B4: 50000 | C4: =B4*12 -> 600000 | D4: =B4*D8 -> 156.288 | E4: =B4*E8 -> 720.192 | F4: =B4*F8 -> 211.2 | G4: =B4*G8 -> 184.8 | H4: =B4*H8 -> 2291.52 | I4: =B4*I8 -> 1716 | J4: =SUM(D4:I4) -> 5280 | L4: 44593 | M4: =J9 -> 5280 | N4: 17225.88 | O4: =M4-N4 -> -11945.88
A5: ANEXO | B5: ALIQ NOMINAL | C5: PARCELA DEDUZIR | D5: ALIQ EFETIVA | E5: ALIQ EFETIVA | F5: ALIQ EFETIVA | G5: ALIQ EFETIVA | H5: ALIQ EFETIVA | I5: ALIQ EFETIVA | L5: 44621 | M5: =J14 -> 6020 | N5: 21331.08 | O5: =M5-N5 -> -15311.08
A6: III | B6: =TABELAS!B25 -> 0.135 | C6: =TABELAS!C25 -> 17640 | D6: =((C4*B6)-C6)/C4 -> 0.1056 | E6: =D6 -> 0.1056 | F6: =E6 -> 0.1056 | G6: =F6 -> 0.1056 | H6: =G6 -> 0.1056 | I6: =H6 -> 0.1056 | L6: 44652 | M6: =J19 -> 5772.5 | N6: 18127.09 | O6: =M6-N6 -> -12354.59
D7: 0.0296 | E7: 0.1364 | F7: 0.04 | G7: 0.035 | H7: 0.434 | I7: 0.325 | L7: 44682 | M7: =J24 -> 5624 | N7: 26870.83 | O7: =M7-N7 -> -21246.83
D8: =D7*D6 -> 0.00312576 | E8: =E7*E6 -> 0.01440384 | F8: =F7*F6 -> 0.004224 | G8: =G7*G6 -> 0.003696 | H8: =H7*H6 -> 0.0458304 | I8: =I7*I6 -> 0.03432 | L8: 44713 | M8: =J29 -> 5525 | N8: 23988.8 | O8: =M8-N8 -> -18463.8
A9: 44593 | B9: 50000 | C9: =50000*12/1 -> 600000 | D9: =B9*D13 -> 156.288 | E9: =B9*E13 -> 720.192 | F9: =B9*F13 -> 211.2 | G9: =B9*G13 -> 184.8 | H9: =B9*H13 -> 2291.52 | I9: =B9*I13 -> 1716 | J9: =SUM(D9:I9) -> 5280 | L9: 44743 | M9: =J34 -> 5454.2857 | N9: 21135.72 | O9: =M9-N9 -> -15681.434
A10: ANEXO | B10: ALIQ NOMINAL | C10: PARCELA DEDUZIR | D10: ALIQ EFETIVA | E10: ALIQ EFETIVA | F10: ALIQ EFETIVA | G10: ALIQ EFETIVA | H10: ALIQ EFETIVA | I10: ALIQ EFETIVA | L10: 44774 | M10: =J39 -> 5463.75 | N10: 30632.19 | O10: =M10-N10 -> -25168.44
A11: V | B11: =B6 -> 0.135 | C11: =C6 -> 17640 | D11: =((C9*B11)-C11)/C9 -> 0.1056 | E11: =D11 -> 0.1056 | F11: =E11 -> 0.1056 | G11: =F11 -> 0.1056 | H11: =G11 -> 0.1056 | I11: =H11 -> 0.1056 | L11: 44805 | M11: =J44 -> 5443.3333 | N11: 27920.89 | O11: =M11-N11 -> -22477.557
D12: 0.0296 | E12: 0.1364 | F12: 0.04 | G12: 0.035 | H12: 0.434 | I12: 0.325 | L12: 44835 | M12: =J49 -> 5427 | N12: 25334.11 | O12: =M12-N12 -> -19907.11
D13: =D12*D11 -> 0.00312576 | E13: =E12*E11 -> 0.01440384 | F13: =F12*F11 -> 0.004224 | G13: =G12*G11 -> 0.003696 | H13: =H12*H11 -> 0.0458304 | I13: =I12*I11 -> 0.03432 | L13: 44866 | M13: =J54 -> 5413.6364 | N13: 23210.14 | O13: =M13-N13 -> -17796.504
A14: 44621 | B14: 50000 | C14: =(B14+B4+B9)*12/2 -> 900000 | D14: =B14*D18 -> 178.192 | E14: =B14*E18 -> 821.128 | F14: =B14*F18 -> 240.8 | G14: =B14*G18 -> 210.7 | H14: =B14*H18 -> 2612.68 | I14: =B14*I18 -> 1956.5 | J14: =SUM(D14:I14) -> 6020 | L14: 44896 | M14: =J59 -> 5402.5 | N14: 15146.07 | O14: =M14-N14 -> -9743.57
A15: ANEXO | B15: ALIQ NOMINAL | C15: PARCELA DEDUZIR | D15: ALIQ EFETIVA | E15: ALIQ EFETIVA | F15: ALIQ EFETIVA | G15: ALIQ EFETIVA | H15: ALIQ EFETIVA | I15: ALIQ EFETIVA | L15: TOTAL | M15: =SUM(M3:M14) -> 66106.005 | N15: =SUM(N3:N14) -> 265713.95 | O15: =M15-N15 -> -199607.94
A16: V | B16: =TABELAS!B26 -> 0.16 | C16: =TABELAS!C26 -> 35640 | D16: =((C14*B16)-C16)/C14 -> 0.1204 | E16: =D16 -> 0.1204 | F16: =E16 -> 0.1204 | G16: =F16 -> 0.1204 | H16: =G16 -> 0.1204 | I16: =H16 -> 0.1204
D17: 0.0296 | E17: 0.1364 | F17: 0.04 | G17: 0.035 | H17: 0.434 | I17: 0.325 | N17: POR MÊS | O17: =O15/12 -> -16633.995
D18: =D17*D16 -> 0.00356384 | E18: =E17*E16 -> 0.01642256 | F18: =F17*F16 -> 0.004816 | G18: =G17*G16 -> 0.004214 | H18: =H17*H16 -> 0.0522536 | I18: =I17*I16 -> 0.03913
A19: 44652 | B19: 50000 | C19: =(B19+B9+B14+B4)*12/3 -> 800000 | D19: =B19*D23 -> 170.866 | E19: =B19*E23 -> 787.369 | F19: =B19*F23 -> 230.9 | G19: =B19*G23 -> 202.0375 | H19: =B19*H23 -> 2505.265 | I19: =B19*I23 -> 1876.0625 | J19: =SUM(D19:I19) -> 5772.5
A20: ANEXO | B20: ALIQ NOMINAL | C20: PARCELA DEDUZIR | D20: ALIQ EFETIVA | E20: ALIQ EFETIVA | F20: ALIQ EFETIVA | G20: ALIQ EFETIVA | H20: ALIQ EFETIVA | I20: ALIQ EFETIVA
A21: V | B21: =B16 -> 0.16 | C21: =C16 -> 35640 | D21: =((C19*B21)-C21)/C19 -> 0.11545 | E21: =D21 -> 0.11545 | F21: =E21 -> 0.11545 | G21: =F21 -> 0.11545 | H21: =G21 -> 0.11545 | I21: =H21 -> 0.11545
D22: 0.0296 | E22: 0.1364 | F22: 0.04 | G22: 0.035 | H22: 0.434 | I22: 0.325
D23: =D22*D21 -> 0.00341732 | E23: =E22*E21 -> 0.01574738 | F23: =F22*F21 -> 0.004618 | G23: =G22*G21 -> 0.00404075 | H23: =H22*H21 -> 0.0501053 | I23: =I22*I21 -> 0.03752125
A24: 44682 | B24: 50000 | C24: =(B24+B14+B19+B9+B4)*12/4 -> 750000 | D24: =B24*D28 -> 156.3472 | E24: =B24*E28 -> 720.9968 | F24: =B24*F28 -> 224.96 | G24: =B24*G28 -> 196.84 | H24: =B24*H28 -> 2440.816 | I24: =B24*I28 -> 1884.04 | J24: =SUM(D24:I24) -> 5624
A25: ANEXO | B25: ALIQ NOMINAL | C25: PARCELA DEDUZIR | D25: ALIQ EFETIVA | E25: ALIQ EFETIVA | F25: ALIQ EFETIVA | G25: ALIQ EFETIVA | H25: ALIQ EFETIVA | I25: ALIQ EFETIVA
A26: V | B26: =B21 -> 0.16 | C26: =C21 -> 35640 | D26: =((C24*B26)-C26)/C24 -> 0.11248 | E26: =D26 -> 0.11248 | F26: =E26 -> 0.11248 | G26: =F26 -> 0.11248 | H26: =G26 -> 0.11248 | I26: =H26 -> 0.11248
D27: 0.0278 | E27: 0.1282 | F27: 0.04 | G27: 0.035 | H27: 0.434 | I27: 0.335
D28: =D27*D26 -> 0.003126944 | E28: =E27*E26 -> 0.014419936 | F28: =F27*F26 -> 0.0044992 | G28: =G27*G26 -> 0.0039368 | H28: =H27*H26 -> 0.04881632 | I28: =I27*I26 -> 0.0376808
A29: 44713 | B29: 50000 | C29: =(B29+B19+B24+B14+B9+B4)*12/5 -> 720000 | D29: =B29*D33 -> 153.595 | E29: =B29*E33 -> 708.305 | F29: =B29*F33 -> 221 | G29: =B29*G33 -> 193.375 | H29: =B29*H33 -> 2397.85 | I29: =B29*I33 -> 1850.875 | J29: =SUM(D29:I29) -> 5525
A30: ANEXO | B30: ALIQ NOMINAL | C30: PARCELA DEDUZIR | D30: ALIQ EFETIVA | E30: ALIQ EFETIVA | F30: ALIQ EFETIVA | G30: ALIQ EFETIVA | H30: ALIQ EFETIVA | I30: ALIQ EFETIVA
A31: V | B31: =B26 -> 0.16 | C31: =C26 -> 35640 | D31: =((C29*B31)-C31)/C29 -> 0.1105 | E31: =D31 -> 0.1105 | F31: =E31 -> 0.1105 | G31: =F31 -> 0.1105 | H31: =G31 -> 0.1105 | I31: =H31 -> 0.1105
D32: 0.0278 | E32: 0.1282 | F32: 0.04 | G32: 0.035 | H32: 0.434 | I32: 0.335
D33: =D32*D31 -> 0.0030719 | E33: =E32*E31 -> 0.0141661 | F33: =F32*F31 -> 0.00442 | G33: =G32*G31 -> 0.0038675 | H33: =H32*H31 -> 0.047957 | I33: =I32*I31 -> 0.0370175
A34: 44743 | B34: 50000 | C34: =(B34+B24+B29+B19+B14+B9+B4)*12/6 -> 700000 | D34: =B34*D38 -> 151.62914 | E34: =B34*E38 -> 699.23943 | F34: =B34*F38 -> 218.17143 | G34: =B34*G38 -> 190.9 | H34: =B34*H38 -> 2367.16 | I34: =B34*I38 -> 1827.1857 | J34: =SUM(D34:I34) -> 5454.2857
A35: ANEXO | B35: ALIQ NOMINAL | C35: PARCELA DEDUZIR | D35: ALIQ EFETIVA | E35: ALIQ EFETIVA | F35: ALIQ EFETIVA | G35: ALIQ EFETIVA | H35: ALIQ EFETIVA | I35: ALIQ EFETIVA
A36: V | B36: =B31 -> 0.16 | C36: =C31 -> 35640 | D36: =((C34*B36)-C36)/C34 -> 0.10908571 | E36: =D36 -> 0.10908571 | F36: =E36 -> 0.10908571 | G36: =F36 -> 0.10908571 | H36: =G36 -> 0.10908571 | I36: =H36 -> 0.10908571
D37: 0.0278 | E37: 0.1282 | F37: 0.04 | G37: 0.035 | H37: 0.434 | I37: 0.335
D38: =D37*D36 -> 0.0030325829 | E38: =E37*E36 -> 0.013984789 | F38: =F37*F36 -> 0.0043634286 | G38: =G37*G36 -> 0.003818 | H38: =H37*H36 -> 0.0473432 | I38: =I37*I36 -> 0.036543714
A39: 44774 | B39: 50000 | C39: =(B39+B29+B34+B24+B19+B14+B9+B4)*12/7 -> 685714.29 | D39: =B39*D43 -> 151.89225 | E39: =B39*E43 -> 700.45275 | F39: =B39*F43 -> 218.55 | G39: =B39*G43 -> 191.23125 | H39: =B39*H43 -> 2371.2675 | I39: =B39*I43 -> 1830.3563 | J39: =SUM(D39:I39) -> 5463.75
A40: ANEXO | B40: ALIQ NOMINAL | C40: PARCELA DEDUZIR | D40: ALIQ EFETIVA | E40: ALIQ EFETIVA | F40: ALIQ EFETIVA | G40: ALIQ EFETIVA | H40: ALIQ EFETIVA | I40: ALIQ EFETIVA
...

Sheet PLANEJAMENTO
A5: PLANEJAMENTO TRIBUTÁRIO
A7: COMPARATIVO FATURAMENTO - SIMPLES NACIONAL
A9: EMPRESA:
A11: PERÍODO: JANEIRO Á DEZEMBRO
A13: SIMPLES NACIONAL - FATURAMENTO R$ 600.000,00
A14: Período | B14: Receita Bruta | D14: Área Federal | J14: Área Estadual ICMS | L14: Área Municipal ISS | N14: Área Previdenciária
A15: Mês/Ano | B15: Mês | C15: Acumulada | D15: PIS | E15: COFINS | F15: IRPJ | G15: CSLL | H15: IPI | N15: INSS - Patr. | O15: VALOR DAS
A16: 44927 | B16: =RBT!E14 -> 200048.11 | C16: =B16 -> 200048.11 | D16: ='SN industria'!D4 -> #DIV/0! | E16: ='SN industria'!E4 -> #DIV/0! | F16: ='SN industria'!F4 -> #DIV/0! | G16: ='SN industria'!G4 -> #DIV/0! | H16: 0 | J16: 0 | L16: ='SN industria'!I4 -> #DIV/0! | N16: ='SN industria'!H4 -> #DIV/0! | O16: =D16+E16+F16+G16+J16+L16+N16 -> #DIV/0!
A17: 44958 | B17: =RBT!E15 -> 433796.09 | C17: =C16+B17 -> 633844.2 | D17: ='SN industria'!D9 -> #DIV/0! | E17: ='SN industria'!E9 -> #DIV/0! | F17: ='SN industria'!F9 -> #DIV/0! | G17: ='SN industria'!G9 -> #DIV/0! | H17: 0 | J17: 0 | L17: ='SN industria'!I9 -> #DIV/0! | N17: ='SN industria'!H9 -> #DIV/0! | O17: =D17+E17+F17+G17+J17+L17+N17 -> #DIV/0!
A18: 44986 | B18: =RBT!E16 -> 363654.01 | C18: =C17+B18 -> 997498.21 | D18: ='SN industria'!D14 -> #DIV/0! | E18: ='SN industria'!E14 -> #DIV/0! | F18: ='SN industria'!F14 -> #DIV/0! | G18: ='SN industria'!G14 -> #DIV/0! | H18: 0 | J18: 0 | L18: ='SN industria'!I14 -> #DIV/0! | N18: ='SN industria'!H14 -> #DIV/0! | O18: =D18+E18+F18+G18+J18+L18+N18 -> #DIV/0!
A19: 45017 | B19: =RBT!E17 -> 446968.74 | C19: =C18+B19 -> 1444466.9 | D19: ='SN industria'!D19 -> #DIV/0! | E19: ='SN industria'!E19 -> #DIV/0! | F19: ='SN industria'!F19 -> #DIV/0! | G19: ='SN industria'!G19 -> #DIV/0! | H19: 0 | J19: 0 | L19: ='SN industria'!I19 -> #DIV/0! | N19: ='SN industria'!H19 -> #DIV/0! | O19: =D19+E19+F19+G19+J19+L19+N19 -> #DIV/0!
A20: 45047 | B20: =RBT!E18 -> 486387.3 | C20: =C19+B20 -> 1930854.2 | D20: ='SN industria'!D24 -> #DIV/0! | E20: ='SN industria'!E24 -> #DIV/0! | F20: ='SN industria'!F24 -> #DIV/0! | G20: ='SN industria'!G24 -> #DIV/0! | H20: 0 | J20: 0 | L20: ='SN industria'!I24 -> #DIV/0! | N20: ='SN industria'!H24 -> #DIV/0! | O20: =D20+E20+F20+G20+J20+L20+N20 -> #DIV/0!
A21: 45078 | B21: =RBT!E19 -> 407179.16 | C21: =C20+B21 -> 2338033.4 | D21: ='SN industria'!D29 -> #DIV/0! | E21: ='SN industria'!E29 -> #DIV/0! | F21: ='SN industria'!F29 -> #DIV/0! | G21: ='SN industria'!G29 -> #DIV/0! | H21: 0 | J21: 0 | L21: ='SN industria'!I29 -> #DIV/0! | N21: ='SN industria'!H29 -> #DIV/0! | O21: =D21+E21+F21+G21+J21+L21+N21 -> #DIV/0!
A22: 45108 | B22: =RBT!E20 -> 389441.14 | C22: =C21+B22 -> 2727474.6 | D22: ='SN industria'!D34 -> #DIV/0! | E22: ='SN industria'!E34 -> #DIV/0! | F22: ='SN industria'!F34 -> #DIV/0! | G22: ='SN industria'!G34 -> #DIV/0! | H22: 0 | J22: 0 | L22: ='SN industria'!I34 -> #DIV/0! | N22: ='SN industria'!H34 -> #DIV/0! | O22: =D22+E22+F22+G22+J22+L22+N22 -> #DIV/0!
A23: 45139 | B23: =RBT!E21 -> 357092.77 | C23: =C22+B23 -> 3084567.3 | D23: ='SN industria'!D39 -> #DIV/0! | E23: ='SN industria'!E39 -> #DIV/0! | F23: ='SN industria'!F39 -> #DIV/0! | G23: ='SN industria'!G39 -> #DIV/0! | H23: 0 | J23: 0 | L23: ='SN industria'!I39 -> #DIV/0! | N23: ='SN industria'!H39 -> #DIV/0! | O23: =D23+E23+F23+G23+J23+L23+N23 -> #DIV/0!
A24: 45170 | B24: =RBT!E22 -> 277903.59 | C24: =C23+B24 -> 3362470.9 | D24: ='SN industria'!D44 -> #DIV/0! | E24: ='SN industria'!E44 -> #DIV/0! | F24: ='SN industria'!F44 -> #DIV/0! | G24: ='SN industria'!G44 -> #DIV/0! | H24: 0 | J24: 0 | L24: ='SN industria'!I44 -> #DIV/0! | N24: ='SN industria'!H44 -> #DIV/0! | O24: =D24+E24+F24+G24+J24+L24+N24 -> #DIV/0!
A25: 45200 | B25: =RBT!E23 -> 497518.5 | C25: =C24+B25 -> 3859989.4 | D25: ='SN industria'!D49 -> #DIV/0! | E25: ='SN industria'!E49 -> #DIV/0! | F25: ='SN industria'!F49 -> #DIV/0! | G25: ='SN industria'!G49 -> #DIV/0! | H25: 0 | J25: 0 | L25: ='SN industria'!I49 -> #DIV/0! | N25: ='SN industria'!H49 -> #DIV/0! | O25: =D25+E25+F25+G25+J25+L25+N25 -> #DIV/0!
A26: 45231 | B26: =RBT!E24 -> 538580.03 | C26: =C25+B26 -> 4398569.4 | D26: ='SN industria'!D54 -> 2888.3556 | E26: ='SN industria'!E54 -> 13334.787 | F26: ='SN industria'!F54 -> 5407.7143 | G26: ='SN industria'!G54 -> 4771.5126 | H26: 0 | J26: 0 | L26: ='SN industria'!I54 -> 0 | N26: ='SN industria'!H54 -> 14950.739 | O26: =D26+E26+F26+G26+J26+L26+N26 -> 41353.109
A27: 45261 | B27: =RBT!E25 -> 296852.7 | C27: =C26+B27 -> 4695422.1 | D27: ='SN industria'!D59 -> #DIV/0! | E27: ='SN industria'!E59 -> #DIV/0! | F27: ='SN industria'!F59 -> #DIV/0! | G27: ='SN industria'!G59 -> #DIV/0! | H27: 0 | J27: 0 | L27: ='SN industria'!I59 -> #DIV/0! | N27: ='SN industria'!H59 -> #DIV/0! | O27: =D27+E27+F27+G27+J27+L27+N27 -> #DIV/0!
A28: TOTAIS =====> | D28: =SUM(D16:D27) -> #DIV/0! | E28: =SUM(E16:E27) -> #DIV/0! | F28: =SUM(F16:F27) -> #DIV/0! | G28: =SUM(G16:G27) -> #DIV/0! | H28: =SUM(H16:H27) -> 0 | J28: =SUM(J16:J27) -> 0 | L28: =SUM(L16:L27) -> #DIV/0! | N28: =SUM(N16:N27) -> #DIV/0! | O28: =D28+E28+F28+G28+J28+L28+N28 -> #DIV/0!
A35: PLANEJAMENTO TRIBUTÁRIO
A37: RESUMO FINAL
A39: Comparação em reais (R$) | H39: Comparação em percentuais (%)
A41: Total de tributos faturamento R$ 600.000,00 anual | D41: =D28+E28+F28+G28+H28+J28+L28+N28 -> #DIV/0! | H41: Faturamento R$ 600.000,00 | K41: =D41/600000 -> #DIV/0!
A43: Total de tributos faturamento R$ 700.000,00 anual | D43: =#REF!+#REF!+#REF!+#REF!+#REF!+#REF!+#REF!+#REF! -> #REF! | H43: Faturamento R$ 700.000,00 | K43: =D43/700000 -> #REF!
A45: Total de tributos faturamento R$ 800.000,00 anual | D45: =#REF!+#REF!+#REF!+#REF!+#REF!+#REF!+#REF!+#REF! -> #REF! | H45: Faturamento R$ 800.000,00 | K45: =D45/800000 -> #REF!
A47: Total de tributos pagos pelo Lucro Real | D47: =#REF!+#REF!+#REF!+#REF!+#REF!+#REF!+#REF!+#REF!+#REF! -> #REF! | H47: Lucro Real | K47: =D47/#REF! -> #REF!
A49: Total de tributos faturamento R$ 900.000,00 anual | D49: =#REF!+#REF!+#REF!+#REF!+#REF!+#REF!+#REF!+#REF! -> #REF! | H49: Faturamento R$ 900.000,00 | K49: =D49/900000 -> #REF!
A52: GRÁFICOS
A74: NOTAS EXPLICATIVAS
A78: ① | B78: em analise utilizado anexo III - PRESTAÇÃO DE SERVIÇO
A80: ②
A82: ③
